<?xml version="1.0" encoding="UTF-8"?>
<!-- Generated by org.testng.reporters.JUnitReportReporter -->
<testsuite hostname="win8-vm" name="com.toolsqa.framework.tests.day2.TestNG_D2_001" tests="5" failures="5" timestamp="7 Jun 2015 17:04:16 GMT" time="0.016" errors="0">
  <testcase name="four" time="0.000" classname="com.toolsqa.framework.tests.day2.TestNG_D2_001">
    <failure type="java.lang.AssertionError" message="expected [false] but found [true]">
      <![CDATA[java.lang.AssertionError: expected [false] but found [true]
	at org.testng.Assert.fail(Assert.java:94)
	at org.testng.Assert.failNotEquals(Assert.java:494)
	at org.testng.Assert.assertEquals(Assert.java:123)
	at org.testng.Assert.assertEquals(Assert.java:286)
	at org.testng.Assert.assertEquals(Assert.java:296)
	at com.toolsqa.framework.tests.day2.TestNG_D2_001.setup(TestNG_D2_001.java:12)
	at sun.reflect.NativeMethodAccessorImpl.invoke0(Native Method)
	at sun.reflect.NativeMethodAccessorImpl.invoke(Unknown Source)
	at sun.reflect.DelegatingMethodAccessorImpl.invoke(Unknown Source)
	at java.lang.reflect.Method.invoke(Unknown Source)
	at org.testng.internal.MethodInvocationHelper.invokeMethod(MethodInvocationHelper.java:84)
	at org.testng.internal.Invoker.invokeConfigurationMethod(Invoker.java:564)
	at org.testng.internal.Invoker.invokeConfigurations(Invoker.java:213)
	at org.testng.internal.Invoker.invokeMethod(Invoker.java:653)
	at org.testng.internal.Invoker.invokeTestMethod(Invoker.java:901)
	at org.testng.internal.Invoker.invokeTestMethods(Invoker.java:1231)
	at org.testng.internal.TestMethodWorker.invokeTestMethods(TestMethodWorker.java:127)
	at org.testng.internal.TestMethodWorker.run(TestMethodWorker.java:111)
	at org.testng.TestRunner.privateRun(TestRunner.java:767)
	at org.testng.TestRunner.run(TestRunner.java:617)
	at org.testng.SuiteRunner.runTest(SuiteRunner.java:334)
	at org.testng.SuiteRunner.runSequentially(SuiteRunner.java:329)
	at org.testng.SuiteRunner.privateRun(SuiteRunner.java:291)
	at org.testng.SuiteRunner.run(SuiteRunner.java:240)
	at org.testng.SuiteRunnerWorker.runSuite(SuiteRunnerWorker.java:52)
	at org.testng.SuiteRunnerWorker.run(SuiteRunnerWorker.java:86)
	at org.testng.TestNG.runSuitesSequentially(TestNG.java:1224)
	at org.testng.TestNG.runSuitesLocally(TestNG.java:1149)
	at org.testng.TestNG.run(TestNG.java:1057)
	at org.testng.remote.RemoteTestNG.run(RemoteTestNG.java:111)
	at org.testng.remote.RemoteTestNG.initAndRun(RemoteTestNG.java:204)
	at org.testng.remote.RemoteTestNG.main(RemoteTestNG.java:175)
]]>
    </failure>
  </testcase> <!-- four -->
  <testcase name="one1" time="0.000" classname="com.toolsqa.framework.tests.day2.TestNG_D2_001">
    <failure type="java.lang.AssertionError" message="expected [false] but found [true]">
      <![CDATA[java.lang.AssertionError: expected [false] but found [true]
	at org.testng.Assert.fail(Assert.java:94)
	at org.testng.Assert.failNotEquals(Assert.java:494)
	at org.testng.Assert.assertEquals(Assert.java:123)
	at org.testng.Assert.assertEquals(Assert.java:286)
	at org.testng.Assert.assertEquals(Assert.java:296)
	at com.toolsqa.framework.tests.day2.TestNG_D2_001.setup(TestNG_D2_001.java:12)
	at sun.reflect.NativeMethodAccessorImpl.invoke0(Native Method)
	at sun.reflect.NativeMethodAccessorImpl.invoke(Unknown Source)
	at sun.reflect.DelegatingMethodAccessorImpl.invoke(Unknown Source)
	at java.lang.reflect.Method.invoke(Unknown Source)
	at org.testng.internal.MethodInvocationHelper.invokeMethod(MethodInvocationHelper.java:84)
	at org.testng.internal.Invoker.invokeConfigurationMethod(Invoker.java:564)
	at org.testng.internal.Invoker.invokeConfigurations(Invoker.java:213)
	at org.testng.internal.Invoker.invokeMethod(Invoker.java:653)
	at org.testng.internal.Invoker.invokeTestMethod(Invoker.java:901)
	at org.testng.internal.Invoker.invokeTestMethods(Invoker.java:1231)
	at org.testng.internal.TestMethodWorker.invokeTestMethods(TestMethodWorker.java:127)
	at org.testng.internal.TestMethodWorker.run(TestMethodWorker.java:111)
	at org.testng.TestRunner.privateRun(TestRunner.java:767)
	at org.testng.TestRunner.run(TestRunner.java:617)
	at org.testng.SuiteRunner.runTest(SuiteRunner.java:334)
	at org.testng.SuiteRunner.runSequentially(SuiteRunner.java:329)
	at org.testng.SuiteRunner.privateRun(SuiteRunner.java:291)
	at org.testng.SuiteRunner.run(SuiteRunner.java:240)
	at org.testng.SuiteRunnerWorker.runSuite(SuiteRunnerWorker.java:52)
	at org.testng.SuiteRunnerWorker.run(SuiteRunnerWorker.java:86)
	at org.testng.TestNG.runSuitesSequentially(TestNG.java:1224)
	at org.testng.TestNG.runSuitesLocally(TestNG.java:1149)
	at org.testng.TestNG.run(TestNG.java:1057)
	at org.testng.remote.RemoteTestNG.run(RemoteTestNG.java:111)
	at org.testng.remote.RemoteTestNG.initAndRun(RemoteTestNG.java:204)
	at org.testng.remote.RemoteTestNG.main(RemoteTestNG.java:175)
]]>
    </failure>
  </testcase> <!-- one1 -->
  <testcase name="three" time="0.000" classname="com.toolsqa.framework.tests.day2.TestNG_D2_001">
    <failure type="java.lang.AssertionError" message="expected [false] but found [true]">
      <![CDATA[java.lang.AssertionError: expected [false] but found [true]
	at org.testng.Assert.fail(Assert.java:94)
	at org.testng.Assert.failNotEquals(Assert.java:494)
	at org.testng.Assert.assertEquals(Assert.java:123)
	at org.testng.Assert.assertEquals(Assert.java:286)
	at org.testng.Assert.assertEquals(Assert.java:296)
	at com.toolsqa.framework.tests.day2.TestNG_D2_001.setup(TestNG_D2_001.java:12)
	at sun.reflect.NativeMethodAccessorImpl.invoke0(Native Method)
	at sun.reflect.NativeMethodAccessorImpl.invoke(Unknown Source)
	at sun.reflect.DelegatingMethodAccessorImpl.invoke(Unknown Source)
	at java.lang.reflect.Method.invoke(Unknown Source)
	at org.testng.internal.MethodInvocationHelper.invokeMethod(MethodInvocationHelper.java:84)
	at org.testng.internal.Invoker.invokeConfigurationMethod(Invoker.java:564)
	at org.testng.internal.Invoker.invokeConfigurations(Invoker.java:213)
	at org.testng.internal.Invoker.invokeMethod(Invoker.java:653)
	at org.testng.internal.Invoker.invokeTestMethod(Invoker.java:901)
	at org.testng.internal.Invoker.invokeTestMethods(Invoker.java:1231)
	at org.testng.internal.TestMethodWorker.invokeTestMethods(TestMethodWorker.java:127)
	at org.testng.internal.TestMethodWorker.run(TestMethodWorker.java:111)
	at org.testng.TestRunner.privateRun(TestRunner.java:767)
	at org.testng.TestRunner.run(TestRunner.java:617)
	at org.testng.SuiteRunner.runTest(SuiteRunner.java:334)
	at org.testng.SuiteRunner.runSequentially(SuiteRunner.java:329)
	at org.testng.SuiteRunner.privateRun(SuiteRunner.java:291)
	at org.testng.SuiteRunner.run(SuiteRunner.java:240)
	at org.testng.SuiteRunnerWorker.runSuite(SuiteRunnerWorker.java:52)
	at org.testng.SuiteRunnerWorker.run(SuiteRunnerWorker.java:86)
	at org.testng.TestNG.runSuitesSequentially(TestNG.java:1224)
	at org.testng.TestNG.runSuitesLocally(TestNG.java:1149)
	at org.testng.TestNG.run(TestNG.java:1057)
	at org.testng.remote.RemoteTestNG.run(RemoteTestNG.java:111)
	at org.testng.remote.RemoteTestNG.initAndRun(RemoteTestNG.java:204)
	at org.testng.remote.RemoteTestNG.main(RemoteTestNG.java:175)
]]>
    </failure>
  </testcase> <!-- three -->
  <testcase name="two" time="0.016" classname="com.toolsqa.framework.tests.day2.TestNG_D2_001">
    <failure type="java.lang.AssertionError" message="expected [false] but found [true]">
      <![CDATA[java.lang.AssertionError: expected [false] but found [true]
	at org.testng.Assert.fail(Assert.java:94)
	at org.testng.Assert.failNotEquals(Assert.java:494)
	at org.testng.Assert.assertEquals(Assert.java:123)
	at org.testng.Assert.assertEquals(Assert.java:286)
	at org.testng.Assert.assertEquals(Assert.java:296)
	at com.toolsqa.framework.tests.day2.TestNG_D2_001.setup(TestNG_D2_001.java:12)
	at sun.reflect.NativeMethodAccessorImpl.invoke0(Native Method)
	at sun.reflect.NativeMethodAccessorImpl.invoke(Unknown Source)
	at sun.reflect.DelegatingMethodAccessorImpl.invoke(Unknown Source)
	at java.lang.reflect.Method.invoke(Unknown Source)
	at org.testng.internal.MethodInvocationHelper.invokeMethod(MethodInvocationHelper.java:84)
	at org.testng.internal.Invoker.invokeConfigurationMethod(Invoker.java:564)
	at org.testng.internal.Invoker.invokeConfigurations(Invoker.java:213)
	at org.testng.internal.Invoker.invokeMethod(Invoker.java:653)
	at org.testng.internal.Invoker.invokeTestMethod(Invoker.java:901)
	at org.testng.internal.Invoker.invokeTestMethods(Invoker.java:1231)
	at org.testng.internal.TestMethodWorker.invokeTestMethods(TestMethodWorker.java:127)
	at org.testng.internal.TestMethodWorker.run(TestMethodWorker.java:111)
	at org.testng.TestRunner.privateRun(TestRunner.java:767)
	at org.testng.TestRunner.run(TestRunner.java:617)
	at org.testng.SuiteRunner.runTest(SuiteRunner.java:334)
	at org.testng.SuiteRunner.runSequentially(SuiteRunner.java:329)
	at org.testng.SuiteRunner.privateRun(SuiteRunner.java:291)
	at org.testng.SuiteRunner.run(SuiteRunner.java:240)
	at org.testng.SuiteRunnerWorker.runSuite(SuiteRunnerWorker.java:52)
	at org.testng.SuiteRunnerWorker.run(SuiteRunnerWorker.java:86)
	at org.testng.TestNG.runSuitesSequentially(TestNG.java:1224)
	at org.testng.TestNG.runSuitesLocally(TestNG.java:1149)
	at org.testng.TestNG.run(TestNG.java:1057)
	at org.testng.remote.RemoteTestNG.run(RemoteTestNG.java:111)
	at org.testng.remote.RemoteTestNG.initAndRun(RemoteTestNG.java:204)
	at org.testng.remote.RemoteTestNG.main(RemoteTestNG.java:175)
]]>
    </failure>
  </testcase> <!-- two -->
  <testcase name="one2" time="0.000" classname="com.toolsqa.framework.tests.day2.TestNG_D2_001">
    <failure type="java.lang.AssertionError" message="expected [false] but found [true]">
      <![CDATA[java.lang.AssertionError: expected [false] but found [true]
	at org.testng.Assert.fail(Assert.java:94)
	at org.testng.Assert.failNotEquals(Assert.java:494)
	at org.testng.Assert.assertEquals(Assert.java:123)
	at org.testng.Assert.assertEquals(Assert.java:286)
	at org.testng.Assert.assertEquals(Assert.java:296)
	at com.toolsqa.framework.tests.day2.TestNG_D2_001.setup(TestNG_D2_001.java:12)
	at sun.reflect.NativeMethodAccessorImpl.invoke0(Native Method)
	at sun.reflect.NativeMethodAccessorImpl.invoke(Unknown Source)
	at sun.reflect.DelegatingMethodAccessorImpl.invoke(Unknown Source)
	at java.lang.reflect.Method.invoke(Unknown Source)
	at org.testng.internal.MethodInvocationHelper.invokeMethod(MethodInvocationHelper.java:84)
	at org.testng.internal.Invoker.invokeConfigurationMethod(Invoker.java:564)
	at org.testng.internal.Invoker.invokeConfigurations(Invoker.java:213)
	at org.testng.internal.Invoker.invokeMethod(Invoker.java:653)
	at org.testng.internal.Invoker.invokeTestMethod(Invoker.java:901)
	at org.testng.internal.Invoker.invokeTestMethods(Invoker.java:1231)
	at org.testng.internal.TestMethodWorker.invokeTestMethods(TestMethodWorker.java:127)
	at org.testng.internal.TestMethodWorker.run(TestMethodWorker.java:111)
	at org.testng.TestRunner.privateRun(TestRunner.java:767)
	at org.testng.TestRunner.run(TestRunner.java:617)
	at org.testng.SuiteRunner.runTest(SuiteRunner.java:334)
	at org.testng.SuiteRunner.runSequentially(SuiteRunner.java:329)
	at org.testng.SuiteRunner.privateRun(SuiteRunner.java:291)
	at org.testng.SuiteRunner.run(SuiteRunner.java:240)
	at org.testng.SuiteRunnerWorker.runSuite(SuiteRunnerWorker.java:52)
	at org.testng.SuiteRunnerWorker.run(SuiteRunnerWorker.java:86)
	at org.testng.TestNG.runSuitesSequentially(TestNG.java:1224)
	at org.testng.TestNG.runSuitesLocally(TestNG.java:1149)
	at org.testng.TestNG.run(TestNG.java:1057)
	at org.testng.remote.RemoteTestNG.run(RemoteTestNG.java:111)
	at org.testng.remote.RemoteTestNG.initAndRun(RemoteTestNG.java:204)
	at org.testng.remote.RemoteTestNG.main(RemoteTestNG.java:175)
]]>
    </failure>
  </testcase> <!-- one2 -->
</testsuite> <!-- com.toolsqa.framework.tests.day2.TestNG_D2_001 -->
